Workbook

Sheet README
A1: ملف تتبّع إكمال الفرونت — Academia
A3: الإصدار | B3: v2.0
A4: آخر تحديث | B4: 2026-10-09
A5: الكاتب الوحيد للملف | B5: المنسّق (جلسة التتبع). الجلسات المتوازية لا تعدّل هذا الملف — ترسل تقريرًا بالصيغة أدناه.
A7: الهدف | B7: إكمال الـ19 متطلبًا (13 غير جاهز + 6 جزئي) من تقرير جاهزية الفرونت بالاعتماد على Swagger الحالي وSRS، مع 7 FRs داعمة لازمة لاكتمال المسارات، بدون تعارض بين عدة جلسات تعمل بالتوازي. هذا الملف خطة وتتبّع فقط — لم تُكتب أي أسطر كود بعد.
A8: المصادر المعتمدة | B8: Swagger_UI.pdf (تاريخ 2026-09-22) · SRS_1__updated_.docx · Frontend_Readiness_Audit_Report.pdf · Frontend.zip (الكود). ملفات md/docs القديمة بالمشروع غير معتمدة.
A9: خريطة الأوراق | B9: Dashboard: ملخص محسوب · BackendChecklist: كل ما نحتاجه من الباك اند + هل وصل · Availability: حجم كل WP + ما يمكن بدؤه الآن + JSON · ParallelPlan: التوازي والدمج · WorkPackages: 20 حزمة (WP-00 + WP-J + 17 + QA) · Tasks: المصدر الوحيد للحالة · FR_Matrix: تتبّع كل FR · UAT: معايير القبول · FileOwnership: مالك كل ملف + كشف التعارض · Contracts: واجهات المكونات + مفاتيح الكاش · API_Map: كل endpoint ↔ الكود · Discrepancies: فروقات Swagger/الكود · OpenQuestions: أسئلة وافتراضات افتراضية · Assumptions_Risks · ChangeRequests · SessionLog · Conventions · Lists
A10: ألوان الخلايا | B10: أصفر فاتح = إدخال يدوي · أزرق فاتح = صيغة (لا تعدّلها) · أبيض = خطة ثابتة (لا تغيّر إلا بقرار المنسّق)
A11: حالات المهام | B11: لم يبدأ · قيد التنفيذ · قيد المراجعة · متوقف · مكتمل · مؤجل. «مكتمل» لا تُعتمد إلا بعد تشغيل npm run validate محليًا (البيئة هنا بلا شبكة).
A12: بروتوكول التحديث | B12: 1) الجلسة تنفّذ WP واحدًا فقط. 2) تنتهي بتقرير نهاية الجلسة (أدناه). 3) المنسّق يلصق التقارير ويطلب «حدّث التتبع» ← يُحدَّث الملف دفعة واحدة، تُرفع النسخة، ويُضاف صف بـ SessionLog.
A13: قالب بداية جلسة | B13: قالب بداية جلسة: «نفّذ WP-xx فقط من ملف التتبع (النسخة vN). اقرأ: WorkPackages + Tasks (مهام WP-xx) + FileOwnership + Contracts + Conventions. لا تعدّل أي ملف ليس مملوكًا لـ WP-xx. المصادر المعتمدة: Swagger + SRS + تقرير الجاهزية. لا تعتمد على ملفات docs القديمة. عند الانتهاء أعطني تقرير الجلسة بصيغة SessionLog.»
A14: قالب نهاية جلسة | B14: قالب تقرير نهاية جلسة (يُنسخ كما هو): WP: ... | الجلسة: ... | التاريخ: ... المهام: [ID: الحالة] ... (مكتمل/قيد التنفيذ/متوقف + سبب) الملفات المعدّلة: ... نتيجة npm run validate: ... افتراضات جديدة / أسئلة مفتوحة: ... طلبات تغيير (CR): ... الخطوة التالية: ...
A15: قبل أي كود | B15: WP-00 أولًا. وقبله: الإجابة على الأسئلة الحاجبة (OpenQuestions) ولصق عينات JSON (API_Map: عمود «عينة مطلوبة»).

Sheet Dashboard
A1: لوحة المتابعة (Dashboard)
A2: كل الأرقام محسوبة تلقائيًا من الأوراق الأخرى. لا تحرّرها يدويًا.
A3: نسخة التتبع | B3: =README!B3 -> v2.0
A4: آخر تحديث | B4: =README!B4 -> 2026-10-09
A6: 1) تقدّم المهام
A7: إجمالي المهام | B7: =COUNTA(Tasks!$A$5:$A$300) -> 129
A8: مكتمل | B8: =COUNTIF(Tasks!$M$5:$M$300,"مكتمل") -> 0
A9: قيد التنفيذ | B9: =COUNTIF(Tasks!$M$5:$M$300,"قيد التنفيذ") -> 2
A10: قيد المراجعة | B10: =COUNTIF(Tasks!$M$5:$M$300,"قيد المراجعة") -> 108
A11: متوقف | B11: =COUNTIF(Tasks!$M$5:$M$300,"متوقف") -> 3
A12: لم يبدأ | B12: =COUNTIF(Tasks!$M$5:$M$300,"لم يبدأ") -> 15
A13: مؤجل | B13: =COUNTIF(Tasks!$M$5:$M$300,"مؤجل") -> 1
A14: نسبة الإنجاز الكلية | B14: =IF(B7=0,0,B8/B7) -> 0
A15: إنجاز Wave 0 | B15: =IF(COUNTIF(Tasks!$C$5:$C$300,"Wave 0")=0,0,COUNTIFS(Tasks!$C$5:$C$300,"Wave 0",Tasks!$M$5:$M$300,"مكتمل")/COUNTIF(Tasks!$C$5:$C$300,"Wave 0")) -> 0
A16: إنجاز Wave 1 | B16: =IF(COUNTIF(Tasks!$C$5:$C$300,"Wave 1")=0,0,COUNTIFS(Tasks!$C$5:$C$300,"Wave 1",Tasks!$M$5:$M$300,"مكتمل")/COUNTIF(Tasks!$C$5:$C$300,"Wave 1")) -> 0
A17: إنجاز Wave 2 | B17: =IF(COUNTIF(Tasks!$C$5:$C$300,"Wave 2")=0,0,COUNTIFS(Tasks!$C$5:$C$300,"Wave 2",Tasks!$M$5:$M$300,"مكتمل")/COUNTIF(Tasks!$C$5:$C$300,"Wave 2")) -> 0
A19: 2) جاهزية الفرونت مقابل الـ30 FR في التقرير
A20: إجمالي FRs ضمن التقرير | B20: =COUNTIF(FR_Matrix!$I$5:$I$60,"نعم") -> 30
A21: الأساس: جاهز بالتقرير | B21: =COUNTIFS(FR_Matrix!$I$5:$I$60,"نعم",FR_Matrix!$G$5:$G$60,"جاهز") -> 11
A22: الأساس: جزئي | B22: =COUNTIFS(FR_Matrix!$I$5:$I$60,"نعم",FR_Matrix!$G$5:$G$60,"جزئي") -> 6
A23: الأساس: غير جاهز | B23: =COUNTIFS(FR_Matrix!$I$5:$I$60,"نعم",FR_Matrix!$G$5:$G$60,"غير جاهز") -> 13
A24: نسبة الجاهزية الأساسية | B24: =IF(B20=0,0,B21/B20) -> 0.36666667
A25: الآن: جاهز (أصلي + أُنجز وتم قبوله) | B25: =COUNTIFS(FR_Matrix!$I$5:$I$60,"نعم",FR_Matrix!$Q$5:$Q$60,"جاهز (أصلي)")+COUNTIFS(FR_Matrix!$I$5:$I$60,"نعم",FR_Matrix!$Q$5:$Q$60,"جاهز") -> 11
A26: الآن: مكتمل – بانتظار UAT | B26: =COUNTIFS(FR_Matrix!$I$5:$I$60,"نعم",FR_Matrix!$Q$5:$Q$60,"مكتمل – بانتظار UAT") -> 0
A27: الآن: قيد التنفيذ | B27: =COUNTIFS(FR_Matrix!$I$5:$I$60,"نعم",FR_Matrix!$Q$5:$Q$60,"قيد التنفيذ") -> 18
A28: الآن: لم يبدأ | B28: =COUNTIFS(FR_Matrix!$I$5:$I$60,"نعم",FR_Matrix!$Q$5:$Q$60,"لم يبدأ") -> 1
A29: نسبة الجاهزية الحالية | B29: =IF(B20=0,0,B25/B20) -> 0.36666667
A30: الهدف | B30: 1
A32: 3) اختبارات القبول (UAT)
A33: إجمالي بنود UAT | B33: =COUNTA(UAT!$A$5:$A$300) -> 64
A34: نجح | B34: =COUNTIF(UAT!$H$5:$H$300,"نجح") -> 0
A35: فشل | B35: =COUNTIF(UAT!$H$5:$H$300,"فشل") -> 0
A36: لم يُختبر | B36: =COUNTIF(UAT!$H$5:$H$300,"لم يُختبر") -> 64
A37: نسبة النجاح | B37: =IF(B33=0,0,B34/B33) -> 0
A39: 4) مخاطر التوازي والعوائق
A40: أسئلة حاجبة مفتوحة | B40: =COUNTIFS(OpenQuestions!$E$5:$E$60,"حاجب",OpenQuestions!$H$5:$H$60,"مفتوح") -> 10
A41: كل الأسئلة المفتوحة | B41: =COUNTIF(OpenQuestions!$H$5:$H$60,"مفتوح") -> 18
A42: فروقات Swagger مفتوحة | B42: =COUNTIF(Discrepancies!$G$5:$G$60,"مفتوح") -> 17
A43: مهام متوقفة | B43: =COUNTIF(Tasks!$M$5:$M$300,"متوقف") -> 3
A44: طلبات تغيير (CR) مفتوحة | B44: =COUNTIF(ChangeRequests!$G$6:$G$40,"مفتوح") -> 5
...

Sheet BackendChecklist
A1: المطلوب من فريق الباك اند (عينات JSON + قرارات) — هل أصبح جاهزًا؟
A2: غيّر عمود «جاهز؟» إلى نعم/جزئي/لا عند الاستلام. عمود «مهام تنتظر» يحسب كم مهمة ما زالت معلّقة عليه. تُحسب «حالة الاعتماد» لكل مهمة بورقة Tasks تلقائيًا.
A4: NE | B4: الوصف | C4: النوع | D4: Endpoint(s) | E4: أسئلة مرتبطة (OpenQuestions) | F4: المطلوب بالضبط | G4: تفتح المهام | H4: جاهز؟ | I4: تاريخ الاستلام | J4: مهام تنتظر الآن | K4: ملاحظات
A5: NE-01 | B5: طلبات الحجز وإعادة الجدولة (جهة المعلم) | C5: عينة JSON | D5: GET Booking/TeacherBookings?status= · GET Booking/TeacherRescheduleRequests?status= | E5: Q-14, Q-22 | F5: رد حقيقي لكل endpoint (حجز واحد على الأقل بكل حالة موجودة)، وأسماء حالات إعادة الجدولة 1..4 — يجب أولًا إصلاح الـ500 (Q-22): الطلب يرجّع 500 حاليًا | G5: T5-01، T5-02، T5-03، T5-04، T5-06 | H5: جزئي | I5: 2026-10-04 | J5: =COUNTIFS(Tasks!$W$5:$W$300,A5,Tasks!$M$5:$M$300,"<>مكتمل") -> 5 | K5: DTO من الكود؛ لكن 500 بالنشر الحي (Q-22) | 2026-10-09: النسخة الجديدة تستخدم BookingProjections.ToDto ويبدو أن 500 أُصلح؛ بانتظار تأكيد حي
A6: NE-02 | B6: تفاصيل حجز الطالب | C6: عينة JSON + قرارات | D6: GET Student/GetBooking?id= | E6: Q-08, Q-09, Q-10 | F6: رد حجز مؤكد وآخر مكتمل؛ هل فيه isRated/تقييم؟ وهل يرجع سياسة الإلغاء/المهلة؟ وقواعد أهلية إعادة الجدولة | G6: S2-01، S2-02، S2-05، S4-02، S4-03 | H6: نعم | I6: 2026-10-04 | J6: =COUNTIFS(Tasks!$W$5:$W$300,A6,Tasks!$M$5:$M$300,"<>مكتمل") -> 5 | K6: DTO من الكود
A7: NE-03 | B7: حالة دفع الحجز | C7: عينة JSON + قرار | D7: GET Student/BookingPayment?bookingId= | E7: Q-06 | F7: رد لحجز مؤكد وآخر رصيده غير كافٍ؛ ومتى يُخصم المبلغ فعليًا | G7: W1-01، W1-05 | H7: نعم | I7: 2026-10-04 | J7: =COUNTIFS(Tasks!$W$5:$W$300,A7,Tasks!$M$5:$M$300,"<>مكتمل") -> 2 | K7: DTO من الكود
A8: NE-04 | B8: طلبات إعادة جدولة الطالب | C8: عينة JSON | D8: GET Student/MyRescheduleRequests | E8: — | F8: رد بطلب معلّق وآخر مرفوض/موافق عليه + أسماء الحالات | G8: S3-02 | H8: نعم | I8: 2026-10-04 | J8: =COUNTIFS(Tasks!$W$5:$W$300,A8,Tasks!$M$5:$M$300,"<>مكتمل") -> 1 | K8: DTO من الكود
A9: NE-05 | B9: تفاصيل الدرس (طالب) | C9: عينة JSON | D9: GET Student/GetLesson?id= | E9: — | F9: درس حضوري (فيه القاعة) وآخر أونلاين (فيه المنصة والرابط وcanJoin) | G9: S5-01، S5-02، S5-03 | H9: نعم | I9: 2026-10-04 | J9: =COUNTIFS(Tasks!$W$5:$W$300,A9,Tasks!$M$5:$M$300,"<>مكتمل") -> 3 | K9: DTO من الكود
A10: NE-06 | B10: تفاصيل الكورس المسجَّل | C10: عينة JSON | D10: GET Student/GetCourse?id= | E10: — | F10: كورس فيه مجموعة ودروس + كورس بلا دروس | G10: S6-01، S6-03، S6-04 | H10: نعم | I10: 2026-10-04 | J10: =COUNTIFS(Tasks!$W$5:$W$300,A10,Tasks!$M$5:$M$300,"<>مكتمل") -> 3 | K10: DTO من الكود
A11: NE-07 | B11: سجل حضور الطالب | C11: عينة JSON | D11: GET Student/Attendance?from&to&courseId | E11: — | F11: رد بسجلات بالحالات الأربع وهل يرجع نسبة؟ | G11: S7-01، S7-03، S7-04، S7-05 | H11: نعم | I11: 2026-10-04 | J11: =COUNTIFS(Tasks!$W$5:$W$300,A11,Tasks!$M$5:$M$300,"<>مكتمل") -> 4 | K11: DTO من الكود
A12: NE-08 | B12: نتائج امتحانات الطالب | C12: عينة JSON | D12: GET Student/ExamResults?courseId | E12: — | F12: رد بعدة نتائج (العنوان/التاريخ/الدرجة/المجموع/الملاحظات) | G12: S8-01، S8-02، S8-03 | H12: نعم | I12: 2026-10-04 | J12: =COUNTIFS(Tasks!$W$5:$W$300,A12,Tasks!$M$5:$M$300,"<>مكتمل") -> 3 | K12: DTO من الكود
A13: NE-09 | B13: كورس المعلم + المجموعة | C13: عينة JSON + قرارات | D13: GET Course/GetMineById?id= | E13: Q-02, Q-03 | F13: شكل الرد (هل فيه groupId/المجموعات؟ هل لكورس أكثر من مجموعة؟)، وهل CreateEdit يأخذ teacherId من الجلسة؟ | G13: T1-07، T2-01، T2-02، T2-04، T2-05، T2-06 | H13: جزئي | I13: 2026-10-04 | J13: =COUNTIFS(Tasks!$W$5:$W$300,A13,Tasks!$M$5:$M$300,"<>مكتمل") -> 6 | K13: CourseListItemDto معروف لكن بلا groupId (Q-02b) | 2026-10-09: CourseListItemDto يحمل TeacherId لكن لا groups
A14: NE-10 | B14: قائمة كورسات المعلم | C14: عينة JSON + قرار | D14: POST Course/GetAll (بحساب معلم) | E14: Q-01 | F14: هل يرجع كورسات المعلم الحالي فقط أم الكل؟ | G14: T1-01 | H14: نعم | I14: 2026-10-04 | J14: =COUNTIFS(Tasks!$W$5:$W$300,A14,Tasks!$M$5:$M$300,"<>مكتمل") -> 1 | K14: يفلتر حسب المعلم
A15: NE-11 | B15: طلاب المجموعة | C15: عينة JSON | D15: GET Course/GetGroupStudents?groupId&keyword | E15: Q-02 | F15: رد بطلاب (الحقول المرجعة) | G15: T3-01، T3-02، T3-03، T3-04 | H15: جزئي | I15: 2026-10-04 | J15: =COUNTIFS(Tasks!$W$5:$W$300,A15,Tasks!$M$5:$M$300,"<>مكتمل") -> 4 | K15: DTO معروف؛ يتطلب groupId (Q-02b)
A16: NE-12 | B16: جدول دروس الكورس (معلم) | C16: عينة JSON | D16: GET Lesson/GetSchedule?courseId&groupId | E16: Q-02 | F16: رد بدروس حضورية وأونلاين | G16: T4-01، T4-05 | H16: نعم | I16: 2026-10-04 | J16: =COUNTIFS(Tasks!$W$5:$W$300,A16,Tasks!$M$5:$M$300,"<>مكتمل") -> 2 | K16: DTO من الكود؛ يكفيه courseId | 2026-10-09: GetSchedule يرجّع الملغاة بلا status، و PlatformOrRoom للأونلاين يحوي الرابط، و Room لا يُحفظ (Q-28..Q-30)
A17: NE-13 | B17: مصدر المادة/التصنيف/الصف (IDs) | C17: عينة JSON + قرار | D17: GET Teacher/CreateEditModal · POST Constant/GetAll | E17: Q-04 | F17: من أين نجلب subjectId/categoryId/gradeId؟ مع الرد الفعلي (وأي parentId لـConstant) | G17: T1-03، T1-04، T1-05، T1-06، S1-03، S1-05 | H17: جزئي | I17: 2026-10-04 | J17: =COUNTIFS(Tasks!$W$5:$W$300,A17,Tasks!$M$5:$M$300,"<>مكتمل") -> 6 | K17: SubjectId اختياري؛ categoryId بلا endpoint (Q-04b)
A18: NE-14 | B18: تحقق اختياري: أنواع موجودة بالكود قد تكون قديمة بعد تحديث الباك اند (لا تحجب أي مهمة) | C18: تحقق اختياري | D18: GET Student/Dashboard · Student/Schedule · Student/Progress · Parent/MyChildren · Parent/ChildAttendance · Parent/ChildExamResults · Wallet/MyWallet · POST Wallet/GetTransactionHistory · Teacher/PublicProfile · Teacher/Availability | E18: — | F18: هذه الردود غير موثّقة بالـSwagger أيضًا، لكن أنواعها منسوخة بالكود من DTOs الباك اند. إن تغيّر الباك اند قد تكون قديمة؛ عيّنة واحدة لكل endpoint تكفي للتأكد | H18: لا | J18: =COUNTIFS(Tasks!$W$5:$W$300,A18,Tasks!$M$5:$M$300,"<>مكتمل") -> 0
A20: قرارات/أسئلة لا تحجب بدء مهمة لكنها تغيّر السلوك أو النصوص (تفاصيلها بورقة OpenQuestions): Q-06 · Q-07 · Q-11 · Q-12 · Q-14 · Q-15 · Q-18 · Q-19 · Q-20 · Q-21. وQ-17 (حسابات اختبار) تحجب QA فقط.

Sheet Availability
A1: التوفّر والتوازي وحجم كل حزمة
A2: محسوب من Tasks. نقاط الجهد = S×1 + M×3 + L×5 (تقدير نسبي للمقارنة فقط، وليس ساعات). الأصفر = قابل للتعديل.
A3: وزن S | B3: 1 | C3: وزن M | D3: 3 | E3: وزن L | F3: 5
A5: WP | B5: الاسم | C5: Wave | D5: عدد المهام | E5: S | F5: M | G5: L | H5: نقاط الجهد | I5: JSON: نعم | J5: JSON: جزئي | K5: JSON: لا | L5: بوابة البدء (WP) | M5: يمكن توازيه مع | N5: ملاحظة
A6: WP-00 | B6: الأساس المشترك (Foundation) | C6: Wave 0 | D6: =COUNTIF(Tasks!$B$5:$B$300,A6) -> 20 | E6: =COUNTIFS(Tasks!$B$5:$B$300,A6,Tasks!$L$5:$L$300,"S") -> 13 | F6: =COUNTIFS(Tasks!$B$5:$B$300,A6,Tasks!$L$5:$L$300,"M") -> 7 | G6: =COUNTIFS(Tasks!$B$5:$B$300,A6,Tasks!$L$5:$L$300,"L") -> 0 | H6: =E6*$B$3+F6*$D$3+G6*$F$3 -> 34 | I6: =COUNTIFS(Tasks!$B$5:$B$300,A6,Tasks!$U$5:$U$300,"نعم") -> 0 | J6: =COUNTIFS(Tasks!$B$5:$B$300,A6,Tasks!$U$5:$U$300,"جزئي") -> 0 | K6: =COUNTIFS(Tasks!$B$5:$B$300,A6,Tasks!$U$5:$U$300,"لا") -> 20 | L6: سُلِّم — بانتظار validate (00-17) | M6: WP-P1، WP-W2 (الآن) | N6: لا يعتمد على JSON. يُغلق بتشغيلك validate محليًا.
A7: WP-J | B7: أنواع الردود الفعلية (بانتظار عينات JSON) | C7: Wave J | D7: =COUNTIF(Tasks!$B$5:$B$300,A7) -> 7 | E7: =COUNTIFS(Tasks!$B$5:$B$300,A7,Tasks!$L$5:$L$300,"S") -> 5 | F7: =COUNTIFS(Tasks!$B$5:$B$300,A7,Tasks!$L$5:$L$300,"M") -> 2 | G7: =COUNTIFS(Tasks!$B$5:$B$300,A7,Tasks!$L$5:$L$300,"L") -> 0 | H7: =E7*$B$3+F7*$D$3+G7*$F$3 -> 11 | I7: =COUNTIFS(Tasks!$B$5:$B$300,A7,Tasks!$U$5:$U$300,"نعم") -> 7 | J7: =COUNTIFS(Tasks!$B$5:$B$300,A7,Tasks!$U$5:$U$300,"جزئي") -> 0 | K7: =COUNTIFS(Tasks!$B$5:$B$300,A7,Tasks!$U$5:$U$300,"لا") -> 0 | L7: عند وصول عينات JSON | M7: — | N7: يفتح المهام المعلّمة JSON=نعم.
A8: WP-T1 | B8: المعلم: قائمة الكورسات + شاشة الكورس + نموذج التفاصيل | C8: Wave 1 | D8: =COUNTIF(Tasks!$B$5:$B$300,A8) -> 8 | E8: =COUNTIFS(Tasks!$B$5:$B$300,A8,Tasks!$L$5:$L$300,"S") -> 4 | F8: =COUNTIFS(Tasks!$B$5:$B$300,A8,Tasks!$L$5:$L$300,"M") -> 4 | G8: =COUNTIFS(Tasks!$B$5:$B$300,A8,Tasks!$L$5:$L$300,"L") -> 0 | H8: =E8*$B$3+F8*$D$3+G8*$F$3 -> 16 | I8: =COUNTIFS(Tasks!$B$5:$B$300,A8,Tasks!$U$5:$U$300,"نعم") -> 3 | J8: =COUNTIFS(Tasks!$B$5:$B$300,A8,Tasks!$U$5:$U$300,"جزئي") -> 4 | K8: =COUNTIFS(Tasks!$B$5:$B$300,A8,Tasks!$U$5:$U$300,"لا") -> 1 | L8: حسب المهمة: «الآن» / «الآن (seam)» / «بعد JSON» | M8: كل WPs Wave 1 الأخرى (ملفات منفصلة) | N8: شغّل المهام الخالية من JSON الآن؛ المعلّمة JSON=نعم تنتظر WP-J.
A9: WP-T2 | B9: المعلم: إعداد المجموعة والجدول المتكرر | C9: Wave 1 | D9: =COUNTIF(Tasks!$B$5:$B$300,A9) -> 6 | E9: =COUNTIFS(Tasks!$B$5:$B$300,A9,Tasks!$L$5:$L$300,"S") -> 4 | F9: =COUNTIFS(Tasks!$B$5:$B$300,A9,Tasks!$L$5:$L$300,"M") -> 2 | G9: =COUNTIFS(Tasks!$B$5:$B$300,A9,Tasks!$L$5:$L$300,"L") -> 0 | H9: =E9*$B$3+F9*$D$3+G9*$F$3 -> 10 | I9: =COUNTIFS(Tasks!$B$5:$B$300,A9,Tasks!$U$5:$U$300,"نعم") -> 1 | J9: =COUNTIFS(Tasks!$B$5:$B$300,A9,Tasks!$U$5:$U$300,"جزئي") -> 4 | K9: =COUNTIFS(Tasks!$B$5:$B$300,A9,Tasks!$U$5:$U$300,"لا") -> 1 | L9: حسب المهمة: «الآن» / «الآن (seam)» / «بعد JSON» | M9: كل WPs Wave 1 الأخرى (ملفات منفصلة) | N9: شغّل المهام الخالية من JSON الآن؛ المعلّمة JSON=نعم تنتظر WP-J.
A10: WP-T3 | B10: المعلم: طلاب المجموعة | C10: Wave 1 | D10: =COUNTIF(Tasks!$B$5:$B$300,A10) -> 4 | E10: =COUNTIFS(Tasks!$B$5:$B$300,A10,Tasks!$L$5:$L$300,"S") -> 4 | F10: =COUNTIFS(Tasks!$B$5:$B$300,A10,Tasks!$L$5:$L$300,"M") -> 0 | G10: =COUNTIFS(Tasks!$B$5:$B$300,A10,Tasks!$L$5:$L$300,"L") -> 0 | H10: =E10*$B$3+F10*$D$3+G10*$F$3 -> 4 | I10: =COUNTIFS(Tasks!$B$5:$B$300,A10,Tasks!$U$5:$U$300,"نعم") -> 4 | J10: =COUNTIFS(Tasks!$B$5:$B$300,A10,Tasks!$U$5:$U$300,"جزئي") -> 0 | K10: =COUNTIFS(Tasks!$B$5:$B$300,A10,Tasks!$U$5:$U$300,"لا") -> 0 | L10: حسب المهمة: «الآن» / «الآن (seam)» / «بعد JSON» | M10: كل WPs Wave 1 الأخرى (ملفات منفصلة) | N10: شغّل المهام الخالية من JSON الآن؛ المعلّمة JSON=نعم تنتظر WP-J.
A11: WP-T4 | B11: المعلم: الدروس (إنشاء/جدولة/تعديل/إلغاء/اجتماع) | C11: Wave 1 | D11: =COUNTIF(Tasks!$B$5:$B$300,A11) -> 8 | E11: =COUNTIFS(Tasks!$B$5:$B$300,A11,Tasks!$L$5:$L$300,"S") -> 5 | F11: =COUNTIFS(Tasks!$B$5:$B$300,A11,Tasks!$L$5:$L$300,"M") -> 3 | G11: =COUNTIFS(Tasks!$B$5:$B$300,A11,Tasks!$L$5:$L$300,"L") -> 0 | H11: =E11*$B$3+F11*$D$3+G11*$F$3 -> 14 | I11: =COUNTIFS(Tasks!$B$5:$B$300,A11,Tasks!$U$5:$U$300,"نعم") -> 1 | J11: =COUNTIFS(Tasks!$B$5:$B$300,A11,Tasks!$U$5:$U$300,"جزئي") -> 1 | K11: =COUNTIFS(Tasks!$B$5:$B$300,A11,Tasks!$U$5:$U$300,"لا") -> 6 | L11: حسب المهمة: «الآن» / «الآن (seam)» / «بعد JSON» | M11: كل WPs Wave 1 الأخرى (ملفات منفصلة) | N11: شغّل المهام الخالية من JSON الآن؛ المعلّمة JSON=نعم تنتظر WP-J.
A12: WP-T5 | B12: المعلم: طلبات الحجز + طلبات إعادة الجدولة + لوحة المعلم | C12: Wave 1 | D12: =COUNTIF(Tasks!$B$5:$B$300,A12) -> 6 | E12: =COUNTIFS(Tasks!$B$5:$B$300,A12,Tasks!$L$5:$L$300,"S") -> 3 | F12: =COUNTIFS(Tasks!$B$5:$B$300,A12,Tasks!$L$5:$L$300,"M") -> 3 | G12: =COUNTIFS(Tasks!$B$5:$B$300,A12,Tasks!$L$5:$L$300,"L") -> 0 | H12: =E12*$B$3+F12*$D$3+G12*$F$3 -> 12 | I12: =COUNTIFS(Tasks!$B$5:$B$300,A12,Tasks!$U$5:$U$300,"نعم") -> 3 | J12: =COUNTIFS(Tasks!$B$5:$B$300,A12,Tasks!$U$5:$U$300,"جزئي") -> 2 | K12: =COUNTIFS(Tasks!$B$5:$B$300,A12,Tasks!$U$5:$U$300,"لا") -> 1 | L12: حسب المهمة: «الآن» / «الآن (seam)» / «بعد JSON» | M12: كل WPs Wave 1 الأخرى (ملفات منفصلة) | N12: شغّل المهام الخالية من JSON الآن؛ المعلّمة JSON=نعم تنتظر WP-J.
A13: WP-S1 | B13: الطالب: شاشة إنشاء الحجز | C13: Wave 1 | D13: =COUNTIF(Tasks!$B$5:$B$300,A13) -> 8 | E13: =COUNTIFS(Tasks!$B$5:$B$300,A13,Tasks!$L$5:$L$300,"S") -> 4 | F13: =COUNTIFS(Tasks!$B$5:$B$300,A13,Tasks!$L$5:$L$300,"M") -> 3 | G13: =COUNTIFS(Tasks!$B$5:$B$300,A13,Tasks!$L$5:$L$300,"L") -> 1 | H13: =E13*$B$3+F13*$D$3+G13*$F$3 -> 18 | I13: =COUNTIFS(Tasks!$B$5:$B$300,A13,Tasks!$U$5:$U$300,"نعم") -> 2 | J13: =COUNTIFS(Tasks!$B$5:$B$300,A13,Tasks!$U$5:$U$300,"جزئي") -> 0 | K13: =COUNTIFS(Tasks!$B$5:$B$300,A13,Tasks!$U$5:$U$300,"لا") -> 6 | L13: حسب المهمة: «الآن» / «الآن (seam)» / «بعد JSON» | M13: كل WPs Wave 1 الأخرى (ملفات منفصلة) | N13: شغّل المهام الخالية من JSON الآن؛ المعلّمة JSON=نعم تنتظر WP-J.
A14: WP-S2 | B14: الطالب: تفاصيل الحجز + الإلغاء + لوحات كورساتي | C14: Wave 1 | D14: =COUNTIF(Tasks!$B$5:$B$300,A14) -> 5 | E14: =COUNTIFS(Tasks!$B$5:$B$300,A14,Tasks!$L$5:$L$300,"S") -> 2 | F14: =COUNTIFS(Tasks!$B$5:$B$300,A14,Tasks!$L$5:$L$300,"M") -> 3 | G14: =COUNTIFS(Tasks!$B$5:$B$300,A14,Tasks!$L$5:$L$300,"L") -> 0 | H14: =E14*$B$3+F14*$D$3+G14*$F$3 -> 11 | I14: =COUNTIFS(Tasks!$B$5:$B$300,A14,Tasks!$U$5:$U$300,"نعم") -> 3 | J14: =COUNTIFS(Tasks!$B$5:$B$300,A14,Tasks!$U$5:$U$300,"جزئي") -> 0 | K14: =COUNTIFS(Tasks!$B$5:$B$300,A14,Tasks!$U$5:$U$300,"لا") -> 2 | L14: حسب المهمة: «الآن» / «الآن (seam)» / «بعد JSON» | M14: كل WPs Wave 1 الأخرى (ملفات منفصلة) | N14: شغّل المهام الخالية من JSON الآن؛ المعلّمة JSON=نعم تنتظر WP-J.
A15: WP-S3 | B15: الطالب: طلب إعادة الجدولة | C15: Wave 1 | D15: =COUNTIF(Tasks!$B$5:$B$300,A15) -> 4 | E15: =COUNTIFS(Tasks!$B$5:$B$300,A15,Tasks!$L$5:$L$300,"S") -> 2 | F15: =COUNTIFS(Tasks!$B$5:$B$300,A15,Tasks!$L$5:$L$300,"M") -> 2 | G15: =COUNTIFS(Tasks!$B$5:$B$300,A15,Tasks!$L$5:$L$300,"L") -> 0 | H15: =E15*$B$3+F15*$D$3+G15*$F$3 -> 8 | I15: =COUNTIFS(Tasks!$B$5:$B$300,A15,Tasks!$U$5:$U$300,"نعم") -> 1 | J15: =COUNTIFS(Tasks!$B$5:$B$300,A15,Tasks!$U$5:$U$300,"جزئي") -> 0 | K15: =COUNTIFS(Tasks!$B$5:$B$300,A15,Tasks!$U$5:$U$300,"لا") -> 3 | L15: حسب المهمة: «الآن» / «الآن (seam)» / «بعد JSON» | M15: كل WPs Wave 1 الأخرى (ملفات منفصلة) | N15: شغّل المهام الخالية من JSON الآن؛ المعلّمة JSON=نعم تنتظر WP-J.
A16: WP-S4 | B16: الطالب: تقييم المعلم | C16: Wave 1 | D16: =COUNTIF(Tasks!$B$5:$B$300,A16) -> 4 | E16: =COUNTIFS(Tasks!$B$5:$B$300,A16,Tasks!$L$5:$L$300,"S") -> 3 | F16: =COUNTIFS(Tasks!$B$5:$B$300,A16,Tasks!$L$5:$L$300,"M") -> 1 | G16: =COUNTIFS(Tasks!$B$5:$B$300,A16,Tasks!$L$5:$L$300,"L") -> 0 | H16: =E16*$B$3+F16*$D$3+G16*$F$3 -> 6 | I16: =COUNTIFS(Tasks!$B$5:$B$300,A16,Tasks!$U$5:$U$300,"نعم") -> 2 | J16: =COUNTIFS(Tasks!$B$5:$B$300,A16,Tasks!$U$5:$U$300,"جزئي") -> 0 | K16: =COUNTIFS(Tasks!$B$5:$B$300,A16,Tasks!$U$5:$U$300,"لا") -> 2 | L16: حسب المهمة: «الآن» / «الآن (seam)» / «بعد JSON» | M16: كل WPs Wave 1 الأخرى (ملفات منفصلة) | N16: شغّل المهام الخالية من JSON الآن؛ المعلّمة JSON=نعم تنتظر WP-J.
A17: WP-S5 | B17: الطالب: تفاصيل الدرس (حضوري/أونلاين) + تحسين الجدول | C17: Wave 1 | D17: =COUNTIF(Tasks!$B$5:$B$300,A17) -> 6 | E17: =COUNTIFS(Tasks!$B$5:$B$300,A17,Tasks!$L$5:$L$300,"S") -> 3 | F17: =COUNTIFS(Tasks!$B$5:$B$300,A17,Tasks!$L$5:$L$300,"M") -> 3 | G17: =COUNTIFS(Tasks!$B$5:$B$300,A17,Tasks!$L$5:$L$300,"L") -> 0 | H17: =E17*$B$3+F17*$D$3+G17*$F$3 -> 12 | I17: =COUNTIFS(Tasks!$B$5:$B$300,A17,Tasks!$U$5:$U$300,"نعم") -> 3 | J17: =COUNTIFS(Tasks!$B$5:$B$300,A17,Tasks!$U$5:$U$300,"جزئي") -> 0 | K17: =COUNTIFS(Tasks!$B$5:$B$300,A17,Tasks!$U$5:$U$300,"لا") -> 3 | L17: حسب المهمة: «الآن» / «الآن (seam)» / «بعد JSON» | M17: كل WPs Wave 1 الأخرى (ملفات منفصلة) | N17: شغّل المهام الخالية من JSON الآن؛ المعلّمة JSON=نعم تنتظر WP-J.
... A24: WP-W2 | B24: المحفظة (معلم): إيداع الأرباح بعد العمولة | C24: Wave 1 | D24: =COUNTIF(Tasks!$B$5:$B$300,A24) -> 4 | E24: =COUNTIFS(Tasks!$B$5:$B$300,A24,Tasks!$L$5:$L$300,"S") -> 3 | F24: =COUNTIFS(Tasks!$B$5:$B$300,A24,Tasks!$L$5:$L$300,"M") -> 1 | G24: =COUNTIFS(Tasks!$B$5:$B$300,A24,Tasks!$L$5:$L$300,"L") -> 0 | H24: =E24*$B$3+F24*$D$3+G24*$F$3 -> 6 | I24: =COUNTIFS(Tasks!$B$5:$B$300,A24,Tasks!$U$5:$U$300,"نعم") -> 0 | J24: =COUNTIFS(Tasks!$B$5:$B$300,A24,Tasks!$U$5:$U$300,"جزئي") -> 0 | K24: =COUNTIFS(Tasks!$B$5:$B$300,A24,Tasks!$U$5:$U$300,"لا") -> 4 | L24: الآن | M24: WP-00، WP-P1 | N24: يعدّل teacher.earnings.tsx فقط؛ يستخدم دوال المحفظة الموجودة.
A25: WP-QA | B25: التكامل والاختبار والتوثيق | C25: Wave 2 | D25: =COUNTIF(Tasks!$B$5:$B$300,A25) -> 9 | E25: =COUNTIFS(Tasks!$B$5:$B$300,A25,Tasks!$L$5:$L$300,"S") -> 3 | F25: =COUNTIFS(Tasks!$B$5:$B$300,A25,Tasks!$L$5:$L$300,"M") -> 4 | G25: =COUNTIFS(Tasks!$B$5:$B$300,A25,Tasks!$L$5:$L$300,"L") -> 2 | H25: =E25*$B$3+F25*$D$3+G25*$F$3 -> 25 | I25: =COUNTIFS(Tasks!$B$5:$B$300,A25,Tasks!$U$5:$U$300,"نعم") -> 0 | J25: =COUNTIFS(Tasks!$B$5:$B$300,A25,Tasks!$U$5:$U$300,"جزئي") -> 0 | K25: =COUNTIFS(Tasks!$B$5:$B$300,A25,Tasks!$U$5:$U$300,"لا") -> 9 | L25: بعد Wave 1 | M25: —
A26: المجموع | D26: =SUM(D6:D25) -> 129 | E26: =SUM(E6:E25) -> 84 | F26: =SUM(F6:F25) -> 42 | G26: =SUM(G6:G25) -> 3 | H26: =SUM(H6:H25) -> 225 | I26: =SUM(I6:I25) -> 42 | J26: =SUM(J6:J25) -> 11 | K26: =SUM(K6:K25) -> 76
A28: المتاح للبدء الآن (بوابة = «الآن»)
A29: عدد المهام | B29: =COUNTIF(Tasks!$V$5:$V$300,"الآن") -> 0
A30: نقاط جهدها | B30: =COUNTIFS(Tasks!$V$5:$V$300,"الآن",Tasks!$L$5:$L$300,"S")*$B$3+COUNTIFS(Tasks!$V$5:$V$300,"الآن",Tasks!$L$5:$L$300,"M")*$D$3+COUNTIFS(Tasks!$V$5:$V$300,"الآن",Tasks!$L$5:$L$300,"L")*$F$3 -> 0

Sheet ParallelPlan
A1: خطة التوازي والدمج
A2: مقترح لتقسيم العمل على جلسات. أي مجموعة من WPs بنفس الـ Wave آمنة التوازي لأن ملفاتها منفصلة (راجع FileOwnership).
A4: المرحلة | B4: المسار/Track | C4: WPs | D4: ملاحظات | E4: شرط البدء | F4: بوابة الإنجاز (Gate)
A5: Wave 0 | B5: Claude ينفّذ كاملًا ثم يشغّل المستخدم validate | C5: WP-00 → W0-Final | D5: WP-00 بالكامل (بلا JSON). بالتوازي معه يمكن للمستخدم بدء WP-P1 وWP-W2 فورًا (يعدّلان ملفات قائمة ولا يمسّان WP-00). WP-J ينتظر العينات. | E5: إجابة Q-01..Q-05 (على الأقل العينات) ← أو البدء بأنواع متساهلة | F5: WP-00 مكتمل + validate أخضر + إغلاق D-01..D-09 + إعلان الملفات المجمّدة
A6: Wave J | B6: عند وصول العينات | C6: WP-J | D6: استبدال PendingResponse بأنواع حقيقية | E6: عينات JSON من المستخدم | F6: J-07 مكتمل
A7: Wave 1 | B7: Track 1: كورسات المعلم | C7: WP-T1 → WP-T3 | D7: T3 يعتمد وظيفيًا على shell من T1 لكن كوديًا مستقل | E7: Wave 0 مغلق | F7: كل مهام الـ WPs مكتملة + validate
A8: Wave 1 | B8: Track 2: مجموعات ودروس | C8: WP-T2 → WP-T4 | D8: الأكبر حجمًا (T4=L)؛ يمكن فصل T4 لجلستين داخليًا لكن بنفس الملفات → جلسة واحدة | E8: Wave 0 مغلق + Q-02 | F8: نفسه
A9: Wave 1 | B9: Track 3: طلبات الحجز (معلم) + أرباح | C9: WP-T5 + WP-W2 | E9: Wave 0 مغلق | F9: نفسه
A10: Wave 1 | B10: Track 4: إنشاء الحجز + تفاصيله | C10: WP-S1 + WP-S2 | D10: يستهلكان stubs لـ W1/S3/S4 | E10: Wave 0 مغلق + Q-04, Q-06 | F10: نفسه
A11: Wave 1 | B11: Track 5: إجراءات الحجز + المحفظة | C11: WP-S3 + WP-S4 + WP-W1 | D11: مكونات صغيرة مستقلة | E11: Wave 0 مغلق | F11: نفسه
A12: Wave 1 | B12: Track 6: الدروس والكورسات (طالب) | C12: WP-S5 + WP-S6 | E12: Wave 0 مغلق | F12: نفسه
A13: Wave 1 | B13: Track 7: أكاديمي + ولي أمر | C13: WP-S7 + WP-S8 + WP-S9 + WP-P1 | D13: كلها صغيرة (S) | E13: Wave 0 مغلق | F13: نفسه
A14: Wave 2 | B14: جلسة واحدة | C14: WP-QA | D14: بعد دمج كل Wave 1 | E14: كل Wave 1 مدموج + Q-17 | F14: validate + e2e + UAT + تحديث التوثيق + إعادة التدقيق
A16: ترتيب الدمج المقترح
A17: 1) WP-00 أولًا (حاجز). 2) بعده أي ترتيب لـ Wave 1 (لا تداخل ملفات). 3) يُفضَّل دمج T1 قبل اختبار T2/T3/T4 معًا، ودمج W1/S3/S4 قبل اختبار S2 كاملًا (اختبار تكاملي فقط).
A18: 4) قبل كل دمج: git pull/rebase، شغّل npm run format && npm run validate، تأكد أن PR لا يلمس routeTree.gen.ts ولا ملفات خارج الملكية.
A19: 5) عند تعارض غير متوقع: أوقف، سجّله في ChangeRequests، لا تحلّه بتعديل ملف غيرك.

Sheet WorkPackages
A1: حزم العمل (Work Packages)
A2: كل WP = وحدة عمل مستقلة بملفات لا يشاركها غيرها. الحالة والنسبة محسوبة تلقائيًا من ورقة Tasks. الأصفر = إدخال.
A4: WP | B4: الاسم | C4: Wave | D4: FRs | E4: النطاق | F4: يعتمد على | G4: الحجم | H4: الفرع (Branch) | I4: المسؤول | J4: الجلسة/Run | K4: عدد المهام | L4: مكتمل | M4: قيد التنفيذ/المراجعة | N4: متوقف | O4: % الإنجاز | P4: الحالة (محسوبة) | Q4: تم الدمج؟ | R4: رابط PR | S4: ملاحظات
A5: WP-00 | B5: الأساس المشترك (Foundation) | C5: Wave 0 | D5: عام | E5: مواءمة طبقة الـ API مع Swagger (طلبات الكتابة + OperationResult) + enums/formatters + مكونات UI مشتركة + تسجيل الصفحات + stubs + routeTree. لا يعتمد على JSON: كل رد غير موثّق يُكتب كـ PendingResponse ويُترك لـ WP-J. ينفّذه Claude بالكامل؛ المستخدم يشغّل validate/توليد routeTree محليًا (00-17). | F5: — | G5: L | H5: feat/wp-00-foundation | I5: Claude + المستخدم | J5: W0-A + W0-B + W0-Final | K5: =COUNTIF(Tasks!$B$5:$B$300,A5) -> 20 | L5: =COUNTIFS(Tasks!$B$5:$B$300,A5,Tasks!$M$5:$M$300,"مكتمل") -> 0 | M5: =COUNTIFS(Tasks!$B$5:$B$300,A5,Tasks!$M$5:$M$300,"قيد التنفيذ")+COUNTIFS(Tasks!$B$5:$B$300,A5,Tasks!$M$5:$M$300,"قيد المراجعة") -> 19 | N5: =COUNTIFS(Tasks!$B$5:$B$300,A5,Tasks!$M$5:$M$300,"متوقف") -> 0 | O5: =IF(K5=0,0,L5/K5) -> 0 | P5: =IF(K5=0,"—",IF(L5=K5,"مكتمل",IF(N5>0,"متوقف",IF(L5+M5>0,"قيد التنفيذ","لم يبدأ")))) -> قيد التنفيذ | Q5: لا
A6: WP-J | B6: أنواع الردود الفعلية (بانتظار عينات JSON) | C6: Wave J | D6: عام | E6: استبدال الأنواع المؤقتة PendingResponse بأنواع حقيقية من عينات JSON، وحسم Q-01..Q-05. لا يبدأ قبل وصول العينات. يمسّ فقط أقسام الأنواع في ملفات API التي أنشأها WP-00. | F6: عينات JSON من المستخدم + إغلاق WP-00 | G6: M | H6: feat/wp-j-response-types | K6: =COUNTIF(Tasks!$B$5:$B$300,A6) -> 7 | L6: =COUNTIFS(Tasks!$B$5:$B$300,A6,Tasks!$M$5:$M$300,"مكتمل") -> 0 | M6: =COUNTIFS(Tasks!$B$5:$B$300,A6,Tasks!$M$5:$M$300,"قيد التنفيذ")+COUNTIFS(Tasks!$B$5:$B$300,A6,Tasks!$M$5:$M$300,"قيد المراجعة") -> 6 | N6: =COUNTIFS(Tasks!$B$5:$B$300,A6,Tasks!$M$5:$M$300,"متوقف") -> 0 | O6: =IF(K6=0,0,L6/K6) -> 0 | P6: =IF(K6=0,"—",IF(L6=K6,"مكتمل",IF(N6>0,"متوقف",IF(L6+M6>0,"قيد التنفيذ","لم يبدأ")))) -> قيد التنفيذ | Q6: لا
A7: WP-T1 | B7: المعلم: قائمة الكورسات + شاشة الكورس + نموذج التفاصيل | C7: Wave 1 | D7: FR-I01, FR-I05 (داعم) | E7: teacher.courses (قائمة) + teacher.course.$id (shell بتبويبات) + تبويب التفاصيل (إنشاء/تعديل كورس حضوري/أونلاين + مسودة). | F7: WP-00 | G7: M | H7: feat/wp-t1-teacher-courses | K7: =COUNTIF(Tasks!$B$5:$B$300,A7) -> 8 | L7: =COUNTIFS(Tasks!$B$5:$B$300,A7,Tasks!$M$5:$M$300,"مكتمل") -> 0 | M7: =COUNTIFS(Tasks!$B$5:$B$300,A7,Tasks!$M$5:$M$300,"قيد التنفيذ")+COUNTIFS(Tasks!$B$5:$B$300,A7,Tasks!$M$5:$M$300,"قيد المراجعة") -> 7 | N7: =COUNTIFS(Tasks!$B$5:$B$300,A7,Tasks!$M$5:$M$300,"متوقف") -> 0 | O7: =IF(K7=0,0,L7/K7) -> 0 | P7: =IF(K7=0,"—",IF(L7=K7,"مكتمل",IF(N7>0,"متوقف",IF(L7+M7>0,"قيد التنفيذ","لم يبدأ")))) -> قيد التنفيذ | Q7: لا
A8: WP-T2 | B8: المعلم: إعداد المجموعة والجدول المتكرر | C8: Wave 1 | D8: FR-I02, FR-I06 | E8: تبويب إعداد المجموعة: الحد الأقصى، أيام الحضور + الوقت، المدة، فترة الكورس (حضوري وأونلاين). | F8: WP-00 | G8: M | H8: feat/wp-t2-group-config | K8: =COUNTIF(Tasks!$B$5:$B$300,A8) -> 6 | L8: =COUNTIFS(Tasks!$B$5:$B$300,A8,Tasks!$M$5:$M$300,"مكتمل") -> 0 | M8: =COUNTIFS(Tasks!$B$5:$B$300,A8,Tasks!$M$5:$M$300,"قيد التنفيذ")+COUNTIFS(Tasks!$B$5:$B$300,A8,Tasks!$M$5:$M$300,"قيد المراجعة") -> 5 | N8: =COUNTIFS(Tasks!$B$5:$B$300,A8,Tasks!$M$5:$M$300,"متوقف") -> 0 | O8: =IF(K8=0,0,L8/K8) -> 0 | P8: =IF(K8=0,"—",IF(L8=K8,"مكتمل",IF(N8>0,"متوقف",IF(L8+M8>0,"قيد التنفيذ","لم يبدأ")))) -> قيد التنفيذ | Q8: لا
A9: WP-T3 | B9: المعلم: طلاب المجموعة | C9: Wave 1 | D9: FR-I03 | E9: تبويب طلاب المجموعة: اسم/هاتف/موقع + بحث + حالة فارغة. | F9: WP-00 | G9: S | H9: feat/wp-t3-group-students | K9: =COUNTIF(Tasks!$B$5:$B$300,A9) -> 4 | L9: =COUNTIFS(Tasks!$B$5:$B$300,A9,Tasks!$M$5:$M$300,"مكتمل") -> 0 | M9: =COUNTIFS(Tasks!$B$5:$B$300,A9,Tasks!$M$5:$M$300,"قيد التنفيذ")+COUNTIFS(Tasks!$B$5:$B$300,A9,Tasks!$M$5:$M$300,"قيد المراجعة") -> 0 | N9: =COUNTIFS(Tasks!$B$5:$B$300,A9,Tasks!$M$5:$M$300,"متوقف") -> 3 | O9: =IF(K9=0,0,L9/K9) -> 0 | P9: =IF(K9=0,"—",IF(L9=K9,"مكتمل",IF(N9>0,"متوقف",IF(L9+M9>0,"قيد التنفيذ","لم يبدأ")))) -> متوقف | Q9: لا
A10: WP-T4 | B10: المعلم: الدروس (إنشاء/جدولة/تعديل/إلغاء/اجتماع) | C10: Wave 1 | D10: FR-I04, FR-I08, FR-I07, FR-I09, FR-I10, FR-I11 | E10: تبويب الدروس: قائمة زمنية + نموذج درس حضوري/أونلاين + تعديل + إعداد الاجتماع + إلغاء بسبب. | F10: WP-00 | G10: L | H10: feat/wp-t4-lessons | K10: =COUNTIF(Tasks!$B$5:$B$300,A10) -> 8 | L10: =COUNTIFS(Tasks!$B$5:$B$300,A10,Tasks!$M$5:$M$300,"مكتمل") -> 0 | M10: =COUNTIFS(Tasks!$B$5:$B$300,A10,Tasks!$M$5:$M$300,"قيد التنفيذ")+COUNTIFS(Tasks!$B$5:$B$300,A10,Tasks!$M$5:$M$300,"قيد المراجعة") -> 8 | N10: =COUNTIFS(Tasks!$B$5:$B$300,A10,Tasks!$M$5:$M$300,"متوقف") -> 0 | O10: =IF(K10=0,0,L10/K10) -> 0 | P10: =IF(K10=0,"—",IF(L10=K10,"مكتمل",IF(N10>0,"متوقف",IF(L10+M10>0,"قيد التنفيذ","لم يبدأ")))) -> قيد التنفيذ | Q10: لا
A11: WP-T5 | B11: المعلم: طلبات الحجز + طلبات إعادة الجدولة + لوحة المعلم | C11: Wave 1 | D11: FR-T10 (داعم), FR-T06 (جهة المعلم), FR-S15 (جهة المعلم) | E11: teacher.bookings: قبول/رفض/إنهاء + قرار إعادة الجدولة + استبدال لوحة المعلم المعطّلة بعرض حقيقي. | F11: WP-00 | G11: M | H11: feat/wp-t5-teacher-bookings | K11: =COUNTIF(Tasks!$B$5:$B$300,A11) -> 6 | L11: =COUNTIFS(Tasks!$B$5:$B$300,A11,Tasks!$M$5:$M$300,"مكتمل") -> 0 | M11: =COUNTIFS(Tasks!$B$5:$B$300,A11,Tasks!$M$5:$M$300,"قيد التنفيذ")+COUNTIFS(Tasks!$B$5:$B$300,A11,Tasks!$M$5:$M$300,"قيد المراجعة") -> 6 | N11: =COUNTIFS(Tasks!$B$5:$B$300,A11,Tasks!$M$5:$M$300,"متوقف") -> 0 | O11: =IF(K11=0,0,L11/K11) -> 0 | P11: =IF(K11=0,"—",IF(L11=K11,"مكتمل",IF(N11>0,"متوقف",IF(L11+M11>0,"قيد التنفيذ","لم يبدأ")))) -> قيد التنفيذ | Q11: لا
A12: WP-S1 | B12: الطالب: شاشة إنشاء الحجز | C12: Wave 1 | D12: FR-T06 (+FR-T05) | E12: book.$teacherId: اختيار الوضع/التاريخ/الوقت/المادة/الصف + تقدير السعر + فحص الرصيد + إرسال الحجز + تفعيل زر الحجز في صفحة المعلم. | F12: WP-00 | G12: L | H12: feat/wp-s1-create-booking | K12: =COUNTIF(Tasks!$B$5:$B$300,A12) -> 8 | L12: =COUNTIFS(Tasks!$B$5:$B$300,A12,Tasks!$M$5:$M$300,"مكتمل") -> 0 | M12: =COUNTIFS(Tasks!$B$5:$B$300,A12,Tasks!$M$5:$M$300,"قيد التنفيذ")+COUNTIFS(Tasks!$B$5:$B$300,A12,Tasks!$M$5:$M$300,"قيد المراجعة") -> 7 | N12: =COUNTIFS(Tasks!$B$5:$B$300,A12,Tasks!$M$5:$M$300,"متوقف") -> 0 | O12: =IF(K12=0,0,L12/K12) -> 0 | P12: =IF(K12=0,"—",IF(L12=K12,"مكتمل",IF(N12>0,"متوقف",IF(L12+M12>0,"قيد التنفيذ","لم يبدأ")))) -> قيد التنفيذ | Q12: لا
A13: WP-S2 | B13: الطالب: تفاصيل الحجز + الإلغاء + لوحات كورساتي | C13: Wave 1 | D13: FR-S14 | E13: booking.$id + إلغاء الحجز + لوحتا (الحجوزات المؤكدة / الطلبات المعلقة) مع سجل المرفوض/الملغى. | F13: WP-00 | G13: M | H13: feat/wp-s2-booking-detail-cancel | K13: =COUNTIF(Tasks!$B$5:$B$300,A13) -> 5 | L13: =COUNTIFS(Tasks!$B$5:$B$300,A13,Tasks!$M$5:$M$300,"مكتمل") -> 0 | M13: =COUNTIFS(Tasks!$B$5:$B$300,A13,Tasks!$M$5:$M$300,"قيد التنفيذ")+COUNTIFS(Tasks!$B$5:$B$300,A13,Tasks!$M$5:$M$300,"قيد المراجعة") -> 5 | N13: =COUNTIFS(Tasks!$B$5:$B$300,A13,Tasks!$M$5:$M$300,"متوقف") -> 0 | O13: =IF(K13=0,0,L13/K13) -> 0 | P13: =IF(K13=0,"—",IF(L13=K13,"مكتمل",IF(N13>0,"متوقف",IF(L13+M13>0,"قيد التنفيذ","لم يبدأ")))) -> قيد التنفيذ | Q13: لا
A14: WP-S3 | B14: الطالب: طلب إعادة الجدولة | C14: Wave 1 | D14: FR-S15 | E14: نافذة طلب إعادة جدولة + لوحة تتبع حالة الطلبات. | F14: WP-00 | G14: S | H14: feat/wp-s3-reschedule | K14: =COUNTIF(Tasks!$B$5:$B$300,A14) -> 4 | L14: =COUNTIFS(Tasks!$B$5:$B$300,A14,Tasks!$M$5:$M$300,"مكتمل") -> 0 | M14: =COUNTIFS(Tasks!$B$5:$B$300,A14,Tasks!$M$5:$M$300,"قيد التنفيذ")+COUNTIFS(Tasks!$B$5:$B$300,A14,Tasks!$M$5:$M$300,"قيد المراجعة") -> 4 | N14: =COUNTIFS(Tasks!$B$5:$B$300,A14,Tasks!$M$5:$M$300,"متوقف") -> 0 | O14: =IF(K14=0,0,L14/K14) -> 0 | P14: =IF(K14=0,"—",IF(L14=K14,"مكتمل",IF(N14>0,"متوقف",IF(L14+M14>0,"قيد التنفيذ","لم يبدأ")))) -> قيد التنفيذ | Q14: لا
A15: WP-S4 | B15: الطالب: تقييم المعلم | C15: Wave 1 | D15: FR-T11 | E15: نافذة تقييم (نجوم + مراجعة) للحجز المكتمل + منع التكرار + تحديث الكاشات. | F15: WP-00 | G15: S | H15: feat/wp-s4-rating | K15: =COUNTIF(Tasks!$B$5:$B$300,A15) -> 4 | L15: =COUNTIFS(Tasks!$B$5:$B$300,A15,Tasks!$M$5:$M$300,"مكتمل") -> 0 | M15: =COUNTIFS(Tasks!$B$5:$B$300,A15,Tasks!$M$5:$M$300,"قيد التنفيذ")+COUNTIFS(Tasks!$B$5:$B$300,A15,Tasks!$M$5:$M$300,"قيد المراجعة") -> 3 | N15: =COUNTIFS(Tasks!$B$5:$B$300,A15,Tasks!$M$5:$M$300,"متوقف") -> 0 | O15: =IF(K15=0,0,L15/K15) -> 0 | P15: =IF(K15=0,"—",IF(L15=K15,"مكتمل",IF(N15>0,"متوقف",IF(L15+M15>0,"قيد التنفيذ","لم يبدأ")))) -> قيد التنفيذ | Q15: لا
A16: WP-S5 | B16: الطالب: تفاصيل الدرس (حضوري/أونلاين) + تحسين الجدول | C16: Wave 1 | D16: FR-S06, FR-S07 | E16: lesson.$id + أعمدة القاعة/المنصة/انضمام في schedule + روابط للتفاصيل. | F16: WP-00 | G16: M | H16: feat/wp-s5-lesson-detail | K16: =COUNTIF(Tasks!$B$5:$B$300,A16) -> 6 | L16: =COUNTIFS(Tasks!$B$5:$B$300,A16,Tasks!$M$5:$M$300,"مكتمل") -> 0 | M16: =COUNTIFS(Tasks!$B$5:$B$300,A16,Tasks!$M$5:$M$300,"قيد التنفيذ")+COUNTIFS(Tasks!$B$5:$B$300,A16,Tasks!$M$5:$M$300,"قيد المراجعة") -> 6 | N16: =COUNTIFS(Tasks!$B$5:$B$300,A16,Tasks!$M$5:$M$300,"متوقف") -> 0 | O16: =IF(K16=0,0,L16/K16) -> 0 | P16: =IF(K16=0,"—",IF(L16=K16,"مكتمل",IF(N16>0,"متوقف",IF(L16+M16>0,"قيد التنفيذ","لم يبدأ")))) -> قيد التنفيذ | Q16: لا
A17: WP-S6 | B17: الطالب: تفاصيل الكورس المسجَّل | C17: Wave 1 | D17: FR-S08 | E17: enrolled-course.$id + لوحة (كورساتي المسجّلة). | F17: WP-00 | G17: M | H17: feat/wp-s6-enrolled-course | K17: =COUNTIF(Tasks!$B$5:$B$300,A17) -> 4 | L17: =COUNTIFS(Tasks!$B$5:$B$300,A17,Tasks!$M$5:$M$300,"مكتمل") -> 0 | M17: =COUNTIFS(Tasks!$B$5:$B$300,A17,Tasks!$M$5:$M$300,"قيد التنفيذ")+COUNTIFS(Tasks!$B$5:$B$300,A17,Tasks!$M$5:$M$300,"قيد المراجعة") -> 4 | N17: =COUNTIFS(Tasks!$B$5:$B$300,A17,Tasks!$M$5:$M$300,"متوقف") -> 0 | O17: =IF(K17=0,0,L17/K17) -> 0 | P17: =IF(K17=0,"—",IF(L17=K17,"مكتمل",IF(N17>0,"متوقف",IF(L17+M17>0,"قيد التنفيذ","لم يبدأ")))) -> قيد التنفيذ | Q17: لا
... A24: WP-QA | B24: التكامل والاختبار والتوثيق | C24: Wave 2 | D24: الكل | E24: validate أخضر + e2e + تشغيل UAT + RTL/موبايل + تحديث README/CHANGELOG/ATLAS + إعادة التدقيق. | F24: كل WP من Wave 1 | G24: L | H24: feat/wp-qa-integration | K24: =COUNTIF(Tasks!$B$5:$B$300,A24) -> 9 | L24: =COUNTIFS(Tasks!$B$5:$B$300,A24,Tasks!$M$5:$M$300,"مكتمل") -> 0 | M24: =COUNTIFS(Tasks!$B$5:$B$300,A24,Tasks!$M$5:$M$300,"قيد التنفيذ")+COUNTIFS(Tasks!$B$5:$B$300,A24,Tasks!$M$5:$M$300,"قيد المراجعة") -> 0 | N24: =COUNTIFS(Tasks!$B$5:$B$300,A24,Tasks!$M$5:$M$300,"متوقف") -> 0 | O24: =IF(K24=0,0,L24/K24) -> 0 | P24: =IF(K24=0,"—",IF(L24=K24,"مكتمل",IF(N24>0,"متوقف",IF(L24+M24>0,"قيد التنفيذ","لم يبدأ")))) -> لم يبدأ | Q24: لا

Sheet Tasks
A1: المهام التفصيلية (Tasks)
A2: المصدر الوحيد لحالة العمل. حدّث الأعمدة الصفراء فقط (الحالة، المسؤول، الجلسة، التواريخ، التحقق، الملاحظات). الأعمدة الزرقاء صيغ.
A4: ID | B4: WP | C4: Wave | D4: FR (أساسي) | E4: النوع | F4: المهمة | G4: التفاصيل / معيار القبول | H4: الملفات (تحت src/ ما لم يُذكر) | I4: Endpoints | J4: تعتمد على | K4: الأولوية | L4: الحجم | M4: الحالة | N4: المسؤول | O4: الجلسة/Run | P4: الفرع (من WP) | Q4: بدأ | R4: اكتمل | S4: تم التحقق؟ (validate+UAT) | T4: ملاحظات | U4: يعتمد على JSON؟ | V4: بوابة البدء | W4: ينتظر (NE) | X4: حالة الاعتماد (محسوبة)
A5: 00-01 | B5: WP-00 | C5: =IFERROR(INDEX(WorkPackages!$C$5:$C$40,MATCH(B5,WorkPackages!$A$5:$A$40,0)),"") -> Wave 0 | D5: عام | E5: API | F5: مواءمة bookings.ts مع Swagger | G5: BookingInput = {teacherId, subjectId, gradeId, teachingMode(1|2), date, startTime, durationMinutes, studentNote}. decide يرسل accept (وليس approve). rate يرسل ratingValue + review. كل الدوال ترجع OperationResult (وليس BookingRow). الحالات أرقام 1..6. (طلبات الكتابة + OperationResult؛ ردود القوائم = PendingResponse) | H5: integrations/backend/bookings.ts | I5: Booking/Submit, Decide, Cancel, Complete, Rate, MyBookings, TeacherBookings | J5: — | K5: P0 | L5: M | M5: قيد المراجعة | N5: Claude | O5: W0 | P5: =IFERROR(INDEX(WorkPackages!$H$5:$H$40,MATCH(B5,WorkPackages!$A$5:$A$40,0)),"") -> feat/wp-00-foundation | S5: لا | T5: سُلِّم في wp-00-files.zip؛ بانتظار 00-17 (routeTree + validate محليًا) | U5: لا | V5: WP-00 (سُلِّم — بانتظار validate) | X5: =IF(W5="","—",IFERROR(IF(INDEX(BackendChecklist!$H$5:$H$30,MATCH(W5,BackendChecklist!$A$5:$A$30,0))="نعم","جاهز للبدء",IF(V5="الآن (بنمط seam)","يبدأ بنمط seam — الربط ينتظر","ينتظر الباك اند")),"؟")) -> —
A6: 00-02 | B6: WP-00 | C6: =IFERROR(INDEX(WorkPackages!$C$5:$C$40,MATCH(B6,WorkPackages!$A$5:$A$40,0)),"") -> Wave 0 | D6: عام | E6: API | F6: إضافة دوال إعادة الجدولة (جهة المعلم) | G6: listTeacherRescheduleRequests(status?) + decideReschedule({requestId, approve, rejectionReason}). | H6: integrations/backend/bookings.ts | I6: Booking/TeacherRescheduleRequests, DecideReschedule | J6: 00-01 | K6: P0 | L6: S | M6: قيد المراجعة | N6: Claude | O6: W0 | P6: =IFERROR(INDEX(WorkPackages!$H$5:$H$40,MATCH(B6,WorkPackages!$A$5:$A$40,0)),"") -> feat/wp-00-foundation | S6: لا | T6: سُلِّم في wp-00-files.zip؛ بانتظار 00-17 (routeTree + validate محليًا) | U6: لا | V6: WP-00 (سُلِّم — بانتظار validate) | X6: =IF(W6="","—",IFERROR(IF(INDEX(BackendChecklist!$H$5:$H$30,MATCH(W6,BackendChecklist!$A$5:$A$30,0))="نعم","جاهز للبدء",IF(V6="الآن (بنمط seam)","يبدأ بنمط seam — الربط ينتظر","ينتظر الباك اند")),"؟")) -> —
A7: 00-03 | B7: WP-00 | C7: =IFERROR(INDEX(WorkPackages!$C$5:$C$40,MATCH(B7,WorkPackages!$A$5:$A$40,0)),"") -> Wave 0 | D7: عام | E7: API | F7: مواءمة lessons.ts | G7: Create/Update/ConfigureMeeting/Cancel ترجع OperationResult؛ getLessonSchedule بنوع مرن حسب العينة Q-05؛ توحيد MeetingPlatform عبر enums.ts. (GetSchedule = PendingResponse) | H7: integrations/backend/lessons.ts | I7: Lesson/Create, Update, ConfigureMeeting, Cancel, GetSchedule | J7: 00-07 | K7: P0 | L7: S | M7: قيد المراجعة | N7: Claude | O7: W0 | P7: =IFERROR(INDEX(WorkPackages!$H$5:$H$40,MATCH(B7,WorkPackages!$A$5:$A$40,0)),"") -> feat/wp-00-foundation | S7: لا | T7: سُلِّم في wp-00-files.zip؛ بانتظار 00-17 (routeTree + validate محليًا) | U7: لا | V7: WP-00 (سُلِّم — بانتظار validate) | X7: =IF(W7="","—",IFERROR(IF(INDEX(BackendChecklist!$H$5:$H$30,MATCH(W7,BackendChecklist!$A$5:$A$30,0))="نعم","جاهز للبدء",IF(V7="الآن (بنمط seam)","يبدأ بنمط seam — الربط ينتظر","ينتظر الباك اند")),"؟")) -> —
A8: 00-04 | B8: WP-00 | C8: =IFERROR(INDEX(WorkPackages!$C$5:$C$40,MATCH(B8,WorkPackages!$A$5:$A$40,0)),"") -> Wave 0 | D8: عام | E8: API | F8: إضافة دوال الكورسات الناقصة | G8: createEditCourse(CourseInput) + configureGroupSchedule(input) + getGroupStudents(groupId, keyword?) + getMyCourse(id) + listMyCourses() (حسب Q-01) + نوع TeacherCourseDetail (حسب Q-02/Q-05). | H8: createEditCourse(CourseInput) + configureGroupSchedule(input) + getGroupStudents(groupId, keyword?) + getMyCourse(id) + listMyCourses(). أجسام الطلب من Swagger؛ كل رد غير موثّق = PendingResponse (يُستبدل في WP-J). | I8: Course/CreateEdit, ConfigureGroupSchedule, GetGroupStudents, GetMineById, GetAll | J8: 00-06, 00-07, 00-21 | K8: P0 | L8: M | M8: قيد المراجعة | N8: Claude | O8: W0 | P8: =IFERROR(INDEX(WorkPackages!$H$5:$H$40,MATCH(B8,WorkPackages!$A$5:$A$40,0)),"") -> feat/wp-00-foundation | S8: لا | T8: سُلِّم في wp-00-files.zip؛ بانتظار 00-17 (routeTree + validate محليًا) | U8: لا | V8: WP-00 (سُلِّم — بانتظار validate) | X8: =IF(W8="","—",IFERROR(IF(INDEX(BackendChecklist!$H$5:$H$30,MATCH(W8,BackendChecklist!$A$5:$A$30,0))="نعم","جاهز للبدء",IF(V8="الآن (بنمط seam)","يبدأ بنمط seam — الربط ينتظر","ينتظر الباك اند")),"؟")) -> —
A9: 00-05 | B9: WP-00 | C9: =IFERROR(INDEX(WorkPackages!$C$5:$C$40,MATCH(B9,WorkPackages!$A$5:$A$40,0)),"") -> Wave 0 | D9: عام | E9: API | F9: إضافة 10 دوال ناقصة لـ student.ts | G9: getStudentBooking, getStudentBookingPayment, studentCancelBooking, requestReschedule, getMyRescheduleRequests, getStudentLesson, getStudentCourse, getStudentAttendance, getStudentExamResults, getStudentProgress + أنواعها. | H9: 10 دوال جديدة: بارامترات/أجسام الطلب من Swagger. الردود غير الموثّقة = PendingResponse؛ الاستثناء getStudentProgress يستخدم StudentProgressDto الموجود بالكود. | I9: Student/GetBooking, BookingPayment, CancelBooking, RequestReschedule, MyRescheduleRequests, GetLesson, GetCourse, Attendance, ExamResults, Progress | J9: 00-06, 00-07, 00-21 | K9: P0 | L9: M | M9: قيد المراجعة | N9: Claude | O9: W0 | P9: =IFERROR(INDEX(WorkPackages!$H$5:$H$40,MATCH(B9,WorkPackages!$A$5:$A$40,0)),"") -> feat/wp-00-foundation | S9: لا | T9: سُلِّم في wp-00-files.zip؛ بانتظار 00-17 (routeTree + validate محليًا) | U9: لا | V9: WP-00 (سُلِّم — بانتظار validate) | X9: =IF(W9="","—",IFERROR(IF(INDEX(BackendChecklist!$H$5:$H$30,MATCH(W9,BackendChecklist!$A$5:$A$30,0))="نعم","جاهز للبدء",IF(V9="الآن (بنمط seam)","يبدأ بنمط seam — الربط ينتظر","ينتظر الباك اند")),"؟")) -> —
A10: 00-06 | B10: WP-00 | C10: =IFERROR(INDEX(WorkPackages!$C$5:$C$40,MATCH(B10,WorkPackages!$A$5:$A$40,0)),"") -> Wave 0 | D10: عام | E10: API | F10: ملف op-result.ts | G10: نوع OperationResult + assertOk(result, fallbackAr, fallbackEn) يرمي Error برسالة الباك اند (مع cleanBackendMessage) عند success=false. | H10: integrations/backend/op-result.ts | I10: — | J10: — | K10: P0 | L10: S | M10: قيد المراجعة | N10: Claude | O10: W0 | P10: =IFERROR(INDEX(WorkPackages!$H$5:$H$40,MATCH(B10,WorkPackages!$A$5:$A$40,0)),"") -> feat/wp-00-foundation | S10: لا | T10: سُلِّم في wp-00-files.zip؛ بانتظار 00-17 (routeTree + validate محليًا) | U10: لا | V10: WP-00 (سُلِّم — بانتظار validate) | X10: =IF(W10="","—",IFERROR(IF(INDEX(BackendChecklist!$H$5:$H$30,MATCH(W10,BackendChecklist!$A$5:$A$30,0))="نعم","جاهز للبدء",IF(V10="الآن (بنمط seam)","يبدأ بنمط seam — الربط ينتظر","ينتظر الباك اند")),"؟")) -> —
A11: 00-07 | B11: WP-00 | C11: =IFERROR(INDEX(WorkPackages!$C$5:$C$40,MATCH(B11,WorkPackages!$A$5:$A$40,0)),"") -> Wave 0 | D11: عام | E11: Lib | F11: ملف enums.ts | G11: BookingStatus(1..6)+labels+tones، DeliveryType، MeetingPlatform، AttendanceStatus، RescheduleStatus (الأسماء تُؤكَّد من Q-05)، DayOfWeek. إزالة التكرار من student.ts/lessons.ts بإعادة التصدير. | H11: lib/enums.ts | I11: — | J11: — | K11: P0 | L11: S | M11: قيد المراجعة | N11: Claude | O11: W0 | P11: =IFERROR(INDEX(WorkPackages!$H$5:$H$40,MATCH(B11,WorkPackages!$A$5:$A$40,0)),"") -> feat/wp-00-foundation | S11: لا | T11: سُلِّم في wp-00-files.zip؛ بانتظار 00-17 (routeTree + validate محليًا) | U11: لا | V11: WP-00 (سُلِّم — بانتظار validate) | X11: =IF(W11="","—",IFERROR(IF(INDEX(BackendChecklist!$H$5:$H$30,MATCH(W11,BackendChecklist!$A$5:$A$30,0))="نعم","جاهز للبدء",IF(V11="الآن (بنمط seam)","يبدأ بنمط seam — الربط ينتظر","ينتظر الباك اند")),"؟")) -> —
A12: 00-08 | B12: WP-00 | C12: =IFERROR(INDEX(WorkPackages!$C$5:$C$40,MATCH(B12,WorkPackages!$A$5:$A$40,0)),"") -> Wave 0 | D12: عام | E12: Lib | F12: ملف format.ts + اختبارات | G12: formatDate, formatTime(HH:mm:ss→HH:mm), dayName(date), formatMoney(₪)، combineDateTime، isHttpUrl (يرفض javascript: وغيره). | H12: lib/format.ts, lib/format.test.ts | I12: — | J12: — | K12: P0 | L12: S | M12: قيد المراجعة | N12: Claude | O12: W0 | P12: =IFERROR(INDEX(WorkPackages!$H$5:$H$40,MATCH(B12,WorkPackages!$A$5:$A$40,0)),"") -> feat/wp-00-foundation | S12: لا | T12: سُلِّم في wp-00-files.zip؛ بانتظار 00-17 (routeTree + validate محليًا) | U12: لا | V12: WP-00 (سُلِّم — بانتظار validate) | X12: =IF(W12="","—",IFERROR(IF(INDEX(BackendChecklist!$H$5:$H$30,MATCH(W12,BackendChecklist!$A$5:$A$30,0))="نعم","جاهز للبدء",IF(V12="الآن (بنمط seam)","يبدأ بنمط seam — الربط ينتظر","ينتظر الباك اند")),"؟")) -> —
A13: 00-09 | B13: WP-00 | C13: =IFERROR(INDEX(WorkPackages!$C$5:$C$40,MATCH(B13,WorkPackages!$A$5:$A$40,0)),"") -> Wave 0 | D13: عام | E13: Component | F13: مكونات UI مشتركة | G13: BookingStatusBadge, StarRating (1..5، قابل للقراءة فقط/للإدخال)، SegmentedTabs (لا يوجد Tabs في المشروع)، ConfirmDialog (فوق alert-dialog). | H13: components/app/booking-status-badge.tsx, components/ui/star-rating.tsx, components/ui/segmented-tabs.tsx, components/app/confirm-dialog.tsx | I13: — | J13: 00-07 | K13: P0 | L13: M | M13: قيد المراجعة | N13: Claude | O13: W0 | P13: =IFERROR(INDEX(WorkPackages!$H$5:$H$40,MATCH(B13,WorkPackages!$A$5:$A$40,0)),"") -> feat/wp-00-foundation | S13: لا | T13: سُلِّم في wp-00-files.zip؛ بانتظار 00-17 (routeTree + validate محليًا) | U13: لا | V13: WP-00 (سُلِّم — بانتظار validate) | X13: =IF(W13="","—",IFERROR(IF(INDEX(BackendChecklist!$H$5:$H$30,MATCH(W13,BackendChecklist!$A$5:$A$30,0))="نعم","جاهز للبدء",IF(V13="الآن (بنمط seam)","يبدأ بنمط seam — الربط ينتظر","ينتظر الباك اند")),"؟")) -> —
A14: 00-10 | B14: WP-00 | C14: =IFERROR(INDEX(WorkPackages!$C$5:$C$40,MATCH(B14,WorkPackages!$A$5:$A$40,0)),"") -> Wave 0 | D14: عام | E14: Lib | F14: ملف query-keys.ts | G14: مصنع مفاتيح react-query موحّد + invalidateBookingQueries(qc, id?) لمنع تضارب/نسيان الإبطال بين الـ WPs. | H14: lib/query-keys.ts | I14: — | J14: — | K14: P0 | L14: S | M14: قيد المراجعة | N14: Claude | O14: W0 | P14: =IFERROR(INDEX(WorkPackages!$H$5:$H$40,MATCH(B14,WorkPackages!$A$5:$A$40,0)),"") -> feat/wp-00-foundation | S14: لا | T14: يتضمن qk.teacherEarningsCredits() (أُضيف من WP-W2 قبل إغلاق WP-00 — بلا CR) | U14: لا | V14: WP-00 (سُلِّم — بانتظار validate) | X14: =IF(W14="","—",IFERROR(IF(INDEX(BackendChecklist!$H$5:$H$30,MATCH(W14,BackendChecklist!$A$5:$A$30,0))="نعم","جاهز للبدء",IF(V14="الآن (بنمط seam)","يبدأ بنمط seam — الربط ينتظر","ينتظر الباك اند")),"؟")) -> —
A15: 00-11 | B15: WP-00 | C15: =IFERROR(INDEX(WorkPackages!$C$5:$C$40,MATCH(B15,WorkPackages!$A$5:$A$40,0)),"") -> Wave 0 | D15: عام | E15: Lib | F15: ملف booking-rules.ts + اختبارات | G15: دوال نقية: canCancel/canReschedule/canRate(booking) بناءً على الحالة والتاريخ (ويُعتمد الباك اند كمرجع نهائي). تستهلكها WP-S2/S3/S4. | H15: lib/booking-rules.ts, lib/booking-rules.test.ts | I15: — | J15: 00-07 | K15: P0 | L15: S | M15: قيد المراجعة | N15: Claude | O15: W0 | P15: =IFERROR(INDEX(WorkPackages!$H$5:$H$40,MATCH(B15,WorkPackages!$A$5:$A$40,0)),"") -> feat/wp-00-foundation | S15: لا | T15: سُلِّم في wp-00-files.zip؛ بانتظار 00-17 (routeTree + validate محليًا) | U15: لا | V15: WP-00 (سُلِّم — بانتظار validate) | X15: =IF(W15="","—",IFERROR(IF(INDEX(BackendChecklist!$H$5:$H$30,MATCH(W15,BackendChecklist!$A$5:$A$30,0))="نعم","جاهز للبدء",IF(V15="الآن (بنمط seam)","يبدأ بنمط seam — الربط ينتظر","ينتظر الباك اند")),"؟")) -> —
A16: 00-12 | B16: WP-00 | C16: =IFERROR(INDEX(WorkPackages!$C$5:$C$40,MATCH(B16,WorkPackages!$A$5:$A$40,0)),"") -> Wave 0 | D16: عام | E16: Test | F16: اختبارات طبقة الـ API | G16: bookings/lessons/student/courses (نمط courses.test.ts: mock لـ apiClient) تغطي المسارات، الحقول، ومعالجة OperationResult. | H16: integrations/backend/bookings.test.ts, lessons.test.ts, student.test.ts, courses.test.ts | I16: كل ما سبق | J16: 00-01..00-06 | K16: P0 | L16: M | M16: قيد المراجعة | N16: Claude | O16: W0 | P16: =IFERROR(INDEX(WorkPackages!$H$5:$H$40,MATCH(B16,WorkPackages!$A$5:$A$40,0)),"") -> feat/wp-00-foundation | S16: لا | T16: تعديل courses.test.ts (ملك WP-00 أصلًا) | U16: لا | V16: WP-00 (سُلِّم — بانتظار validate) | X16: =IF(W16="","—",IFERROR(IF(INDEX(BackendChecklist!$H$5:$H$30,MATCH(W16,BackendChecklist!$A$5:$A$30,0))="نعم","جاهز للبدء",IF(V16="الآن (بنمط seam)","يبدأ بنمط seam — الربط ينتظر","ينتظر الباك اند")),"؟")) -> —
... A22: 00-19 | B22: WP-00 | C22: =IFERROR(INDEX(WorkPackages!$C$5:$C$40,MATCH(B22,WorkPackages!$A$5:$A$40,0)),"") -> Wave 0 | D22: عام | E22: Nav | F22: (اختياري) مطابقة القائمة الجانبية لمسارات التفاصيل | G22: app-sidebar يحدد الوحدة النشطة بـ startsWith على مسارات PAGES؛ مسارات مثل /lesson/$id لن تفتح مجموعتها. تحسين اختياري. | H22: components/admin/app-sidebar.tsx | I22: — | J22: 00-13 | K22: P2 | L22: S | M22: قيد المراجعة | N22: Claude | O22: W0 | P22: =IFERROR(INDEX(WorkPackages!$H$5:$H$40,MATCH(B22,WorkPackages!$A$5:$A$40,0)),"") -> feat/wp-00-foundation | S22: لا | T22: تعديل app-sidebar.tsx ضمن 00-19 الاختيارية (DETAIL_ROUTE_OWNERS) | U22: لا | V22: WP-00 (سُلِّم — بانتظار validate) | X22: =IF(W22="","—",IFERROR(IF(INDEX(BackendChecklist!$H$5:$H$30,MATCH(W22,BackendChecklist!$A$5:$A$30,0))="نعم","جاهز للبدء",IF(V22="الآن (بنمط seam)","يبدأ بنمط seam — الربط ينتظر","ينتظر الباك اند")),"؟")) -> —
A23: 00-20 | B23: WP-00 | C23: =IFERROR(INDEX(WorkPackages!$C$5:$C$40,MATCH(B23,WorkPackages!$A$5:$A$40,0)),"") -> Wave 0 | D23: عام | E23: Tracker | F23: إغلاق Wave 0 وتجميد الملفات | G23: تحديث التتبع: Wave 0 مكتمل + إعلان قائمة الملفات المجمّدة + تفعيل Wave 1. | H23: هذا الملف | I23: — | J23: 00-01..00-17, 00-19, 00-21 | K23: P0 | L23: S | M23: لم يبدأ | N23: Claude | O23: W0-Final | P23: =IFERROR(INDEX(WorkPackages!$H$5:$H$40,MATCH(B23,WorkPackages!$A$5:$A$40,0)),"") -> feat/wp-00-foundation | S23: لا | U23: لا | V23: WP-00 (سُلِّم — بانتظار validate) | X23: =IF(W23="","—",IFERROR(IF(INDEX(BackendChecklist!$H$5:$H$30,MATCH(W23,BackendChecklist!$A$5:$A$30,0))="نعم","جاهز للبدء",IF(V23="الآن (بنمط seam)","يبدأ بنمط seam — الربط ينتظر","ينتظر الباك اند")),"؟")) -> —
A24: T1-01 | B24: WP-T1 | C24: =IFERROR(INDEX(WorkPackages!$C$5:$C$40,MATCH(B24,WorkPackages!$A$5:$A$40,0)),"") -> Wave 1 | D24: FR-I01 | E24: UI | F24: قائمة كورسات المعلم | G24: استبدال placeholder «قيد التطوير» بقائمة حقيقية: العنوان، النوع (حضوري/أونلاين)، الحالة (مسودة/منشور/مؤرشف)، السعر، السعة. حالات تحميل/خطأ/فارغ. حذف نص P1-1 القديم. | H24: routes/_authenticated/teacher.courses.tsx | I24: Course/GetAll (أو بديل حسب Q-01) | J24: WP-00 | K24: P0 | L24: M | M24: قيد المراجعة | N24: Claude | O24: Claude دفعة 4 (منفّذ) | P24: =IFERROR(INDEX(WorkPackages!$H$5:$H$40,MATCH(B24,WorkPackages!$A$5:$A$40,0)),"") -> feat/wp-t1-teacher-courses | S24: لا | T24: teacher.courses.tsx: Course/GetAll (Q-01 مؤكَّد بالكود: كورسات المعلم فقط وبكل الحالات، pageSize≤100)؛ lib/teacher-courses.ts؛ CourseStatus أُضيف لـenums.ts؛ بانتظار validate أخضر عند المستخدم (آخر تشغيل 2026-10-08: typecheck فشل وtest 320/323 بسبب عدم نسخ ملفات دفعة 4 — حُلّ بـfix-pack-1) | U24: نعم | V24: بعد JSON | W24: NE-10 | X24: =IF(W24="","—",IFERROR(IF(INDEX(BackendChecklist!$H$5:$H$30,MATCH(W24,BackendChecklist!$A$5:$A$30,0))="نعم","جاهز للبدء",IF(V24="الآن (بنمط seam)","يبدأ بنمط seam — الربط ينتظر","ينتظر الباك اند")),"؟")) -> جاهز للبدء
A25: T1-02 | B25: WP-T1 | C25: =IFERROR(INDEX(WorkPackages!$C$5:$C$40,MATCH(B25,WorkPackages!$A$5:$A$40,0)),"") -> Wave 1 | D25: FR-I01 | E25: UI | F25: أزرار «إنشاء كورس حضوري/أونلاين» | G25: تنقّل إلى /teacher/course/new?type=1|2 (التحقق من search param بـ zod). | H25: routes/_authenticated/teacher.courses.tsx | I25: — | J25: T1-01 | K25: P1 | L25: S | M25: قيد المراجعة | N25: المستخدم | O25: A-user (منفّذ) | P25: =IFERROR(INDEX(WorkPackages!$H$5:$H$40,MATCH(B25,WorkPackages!$A$5:$A$40,0)),"") -> feat/wp-t1-teacher-courses | S25: لا | T25: نفّذه المستخدم؛ أضاف validateSearch (zod) لـteacher.course.$id.tsx (ملف T1) كي يقبل Link search بـtsc | U25: لا | V25: منفّذ — قيد المراجعة | X25: =IF(W25="","—",IFERROR(IF(INDEX(BackendChecklist!$H$5:$H$30,MATCH(W25,BackendChecklist!$A$5:$A$30,0))="نعم","جاهز للبدء",IF(V25="الآن (بنمط seam)","يبدأ بنمط seam — الربط ينتظر","ينتظر الباك اند")),"؟")) -> —
A26: T1-03 | B26: WP-T1 | C26: =IFERROR(INDEX(WorkPackages!$C$5:$C$40,MATCH(B26,WorkPackages!$A$5:$A$40,0)),"") -> Wave 1 | D26: FR-I01 | E26: UI | F26: نموذج تفاصيل الكورس (حضوري) | G26: الحقول: العنوان، الوصف، المادة، التصنيف، الصف، السعر، الحد الأقصى، اسم المجموعة. تحقق بـ zod ورسائل. إرسال CreateEdit ثم الانتقال لـ /teacher/course/{returnId}. | H26: components/teacher/course-details-tab.tsx | I26: Course/CreateEdit | J26: T1-05 | K26: P0 | L26: M | M26: قيد المراجعة | N26: Claude | O26: B (منفّذ) | P26: =IFERROR(INDEX(WorkPackages!$H$5:$H$40,MATCH(B26,WorkPackages!$A$5:$A$40,0)),"") -> feat/wp-t1-teacher-courses | S26: لا | T26: نفّذه Claude؛ course-details-tab.tsx + course-form-schema.ts: نموذج الكورس كامل (تحقق + جسم CreateEdit + الانتقال لـ/teacher/course/{id}). الحفظ معطّل بنص صادق حتى قوائم المادة/التصنيف (NE-13/Q-04)؛ التعديل معطّل حتى courseToDraft (J-05) — بانتظار validate | U26: جزئي | V26: منفّذ — قيد المراجعة | W26: NE-13 | X26: =IF(W26="","—",IFERROR(IF(INDEX(BackendChecklist!$H$5:$H$30,MATCH(W26,BackendChecklist!$A$5:$A$30,0))="نعم","جاهز للبدء",IF(V26="الآن (بنمط seam)","يبدأ بنمط seam — الربط ينتظر","ينتظر الباك اند")),"؟")) -> ينتظر الباك اند
A27: T1-04 | B27: WP-T1 | C27: =IFERROR(INDEX(WorkPackages!$C$5:$C$40,MATCH(B27,WorkPackages!$A$5:$A$40,0)),"") -> Wave 1 | D27: FR-I05 | E27: UI | F27: نموذج تفاصيل الكورس (أونلاين) | G27: نفس النموذج مع deliveryType=2 وتلميحات خاصة بالأونلاين (المنصة تُحدَّد على مستوى الدرس FR-I07). | H27: components/teacher/course-details-tab.tsx | I27: Course/CreateEdit | J27: T1-03 | K27: P1 | L27: S | M27: قيد المراجعة | N27: Claude | O27: B (منفّذ) | P27: =IFERROR(INDEX(WorkPackages!$H$5:$H$40,MATCH(B27,WorkPackages!$A$5:$A$40,0)),"") -> feat/wp-t1-teacher-courses | S27: لا | T27: نفّذه Claude؛ نفس النموذج مع deliveryType=2 (أونلاين) + تلميح أن المنصة تُحدَّد لكل درس — بانتظار validate | U27: جزئي | V27: منفّذ — قيد المراجعة | W27: NE-13 | X27: =IF(W27="","—",IFERROR(IF(INDEX(BackendChecklist!$H$5:$H$30,MATCH(W27,BackendChecklist!$A$5:$A$30,0))="نعم","جاهز للبدء",IF(V27="الآن (بنمط seam)","يبدأ بنمط seam — الربط ينتظر","ينتظر الباك اند")),"؟")) -> ينتظر الباك اند
A28: T1-05 | B28: WP-T1 | C28: =IFERROR(INDEX(WorkPackages!$C$5:$C$40,MATCH(B28,WorkPackages!$A$5:$A$40,0)),"") -> Wave 1 | D28: FR-I01 | E28: UI | F28: مصادر المادة/التصنيف/الصف | G28: قوائم الاختيار من endpoints مؤكَّدة (Q-04). لو القائمة فاضية: رسالة صادقة بدل بيانات مخترعة. | H28: components/teacher/course-details-tab.tsx | I28: Teacher/CreateEditModal, Constant/GetAll (يُحسم بـ Q-04) | J28: WP-00 | K28: P0 | L28: M | M28: لم يبدأ | P28: =IFERROR(INDEX(WorkPackages!$H$5:$H$40,MATCH(B28,WorkPackages!$A$5:$A$40,0)),"") -> feat/wp-t1-teacher-courses | S28: لا | U28: نعم | V28: بعد JSON | W28: NE-13 | X28: =IF(W28="","—",IFERROR(IF(INDEX(BackendChecklist!$H$5:$H$30,MATCH(W28,BackendChecklist!$A$5:$A$30,0))="نعم","جاهز للبدء",IF(V28="الآن (بنمط seam)","يبدأ بنمط seam — الربط ينتظر","ينتظر الباك اند")),"؟")) -> ينتظر الباك اند
A29: T1-06 | B29: WP-T1 | C29: =IFERROR(INDEX(WorkPackages!$C$5:$C$40,MATCH(B29,WorkPackages!$A$5:$A$40,0)),"") -> Wave 1 | D29: FR-I01 | E29: UI | F29: مسار «حفظ كمسودة / نشر» | G29: saveAsDraft + تبديل النشر؛ إظهار حالة الكورس بعد الحفظ. | H29: components/teacher/course-details-tab.tsx | I29: Course/CreateEdit | J29: T1-03 | K29: P1 | L29: S | M29: قيد المراجعة | N29: Claude | O29: B (منفّذ) | P29: =IFERROR(INDEX(WorkPackages!$H$5:$H$40,MATCH(B29,WorkPackages!$A$5:$A$40,0)),"") -> feat/wp-t1-teacher-courses | S29: لا | T29: نفّذه Claude؛ زرّا «حفظ كمسودة» و«حفظ ونشر» (saveAsDraft) — بانتظار validate | U29: جزئي | V29: منفّذ — قيد المراجعة | W29: NE-13 | X29: =IF(W29="","—",IFERROR(IF(INDEX(BackendChecklist!$H$5:$H$30,MATCH(W29,BackendChecklist!$A$5:$A$30,0))="نعم","جاهز للبدء",IF(V29="الآن (بنمط seam)","يبدأ بنمط seam — الربط ينتظر","ينتظر الباك اند")),"؟")) -> ينتظر الباك اند
A30: T1-07 | B30: WP-T1 | C30: =IFERROR(INDEX(WorkPackages!$C$5:$C$40,MATCH(B30,WorkPackages!$A$5:$A$40,0)),"") -> Wave 1 | D30: FR-I01 | E30: UI | F30: Shell شاشة الكورس + التبويبات | G30: teacher.course.$id: ترويسة + SegmentedTabs عبر ?tab= (details|group|students|lessons)، تعطيل التبويبات قبل حفظ الكورس، تمرير course للتبويبات حسب العقد C-01. | H30: routes/_authenticated/teacher.course.$id.tsx | I30: Course/GetMineById | J30: WP-00 | K30: P0 | L30: M | M30: قيد التنفيذ | N30: Claude | O30: Claude دفعة 4 | P30: =IFERROR(INDEX(WorkPackages!$H$5:$H$40,MATCH(B30,WorkPackages!$A$5:$A$40,0)),"") -> feat/wp-t1-teacher-courses | S30: لا | T30: جزئي: resolveCourseDeliveryType يقرأ deliveryType من الرد؛ resolveGroupId/courseToDraft ما زالتا null (Q-02b/NE-09) | U30: نعم | V30: بعد JSON | W30: NE-09 | X30: =IF(W30="","—",IFERROR(IF(INDEX(BackendChecklist!$H$5:$H$30,MATCH(W30,BackendChecklist!$A$5:$A$30,0))="نعم","جاهز للبدء",IF(V30="الآن (بنمط seam)","يبدأ بنمط seam — الربط ينتظر","ينتظر الباك اند")),"؟")) -> ينتظر الباك اند
A31: T1-08 | B31: WP-T1 | C31: =IFERROR(INDEX(WorkPackages!$C$5:$C$40,MATCH(B31,WorkPackages!$A$5:$A$40,0)),"") -> Wave 1 | D31: FR-I01 | E31: Test | F31: اختبارات مخطط التحقق | G31: اختبارات vitest لقواعد النموذج (حقول مطلوبة، سعر ≥ 0، سعة ≥ 1). | H31: components/teacher/course-details-tab.test.ts | I31: — | J31: T1-03 | K31: P1 | L31: S | M31: قيد المراجعة | N31: Claude | O31: B (منفّذ) | P31: =IFERROR(INDEX(WorkPackages!$H$5:$H$40,MATCH(B31,WorkPackages!$A$5:$A$40,0)),"") -> feat/wp-t1-teacher-courses | S31: لا | T31: نفّذه Claude؛ course-details-tab.test.ts (12 فحصًا) — بانتظار validate | U31: جزئي | V31: منفّذ — قيد المراجعة | X31: =IF(W31="","—",IFERROR(IF(INDEX(BackendChecklist!$H$5:$H$30,MATCH(W31,BackendChecklist!$A$5:$A$30,0))="نعم","جاهز للبدء",IF(V31="الآن (بنمط seam)","يبدأ بنمط seam — الربط ينتظر","ينتظر الباك اند")),"؟")) -> —
A32: T2-01 | B32: WP-T2 | C32: =IFERROR(INDEX(WorkPackages!$C$5:$C$40,MATCH(B32,WorkPackages!$A$5:$A$40,0)),"") -> Wave 1 | D32: FR-I02 | E32: UI | F32: نموذج إعداد مجموعة حضورية | G32: الحد الأقصى للطلاب، تاريخ بداية/نهاية الكورس، مدة الدرس الافتراضية، صفوف أيام الحضور (يوم + وقت) قابلة للإضافة/الحذف → ConfigureGroupSchedule. | H32: components/teacher/group-config-tab.tsx | I32: Course/ConfigureGroupSchedule | J32: WP-00 | K32: P0 | L32: M | M32: قيد المراجعة | N32: Claude | O32: B (منفّذ) | P32: =IFERROR(INDEX(WorkPackages!$H$5:$H$40,MATCH(B32,WorkPackages!$A$5:$A$40,0)),"") -> feat/wp-t2-group-config | S32: لا | T32: نفّذه Claude؛ group-config-tab.tsx + group-schedule-form.ts: النموذج كامل؛ الحفظ معطّل حتى groupId (course-seams → J-05/Q-02) — بانتظار validate | U32: جزئي | V32: منفّذ — قيد المراجعة | W32: NE-09 | X32: =IF(W32="","—",IFERROR(IF(INDEX(BackendChecklist!$H$5:$H$30,MATCH(W32,BackendChecklist!$A$5:$A$30,0))="نعم","جاهز للبدء",IF(V32="الآن (بنمط seam)","يبدأ بنمط seam — الربط ينتظر","ينتظر الباك اند")),"؟")) -> ينتظر الباك اند
A33: T2-02 | B33: WP-T2 | C33: =IFERROR(INDEX(WorkPackages!$C$5:$C$40,MATCH(B33,WorkPackages!$A$5:$A$40,0)),"") -> Wave 1 | D33: FR-I06 | E33: UI | F33: نفس النموذج للمجموعة الأونلاين | G33: حسب deliveryType للكورس: عناوين ونصوص مساعدة مختلفة، نفس الحقول. | H33: components/teacher/group-config-tab.tsx | I33: Course/ConfigureGroupSchedule | J33: T2-01 | K33: P0 | L33: S | M33: قيد المراجعة | N33: Claude | O33: B (منفّذ) | P33: =IFERROR(INDEX(WorkPackages!$H$5:$H$40,MATCH(B33,WorkPackages!$A$5:$A$40,0)),"") -> feat/wp-t2-group-config | S33: لا | T33: نفّذه Claude؛ نفس النموذج: العنوان فقط حسب نوع الكورس (seam) — بانتظار validate | U33: جزئي | V33: منفّذ — قيد المراجعة | W33: NE-09 | X33: =IF(W33="","—",IFERROR(IF(INDEX(BackendChecklist!$H$5:$H$30,MATCH(W33,BackendChecklist!$A$5:$A$30,0))="نعم","جاهز للبدء",IF(V33="الآن (بنمط seam)","يبدأ بنمط seam — الربط ينتظر","ينتظر الباك اند")),"؟")) -> ينتظر الباك اند
